<?xml version="1.0" ?>
<!-- =================================================================================== -->
<!-- |    This document was autogenerated by xacro from /workspaces/src/franka_description/robots/fr3/fr3.urdf.xacro | -->
<!-- |    EDITING THIS FILE BY HAND IS NOT RECOMMENDED                                 | -->
<!-- =================================================================================== -->
<robot name="fr3">
  <!-- safety_distance: Minimum safety distance in [m] by which the collision volumes are expanded and which is enforced during robot motions -->
  <!-- arm_id: Namespace of the robot arm. Serves to differentiate between arms in case of multiple instances. -->
  <!-- joint_limits: description of the joint limits that comes from a YAML file. Example definition: ${xacro.load_yaml('$(find franka_description)/robots/fr3/joint_limits.yaml')} -->
  <!-- kinematics: description of the kinematics that comes from a YAML file. Example definition: ${xacro.load_yaml('$(find franka_description)/robots/fr3/kinematics.yaml')} -->
  <!-- inertials: description of the inertials that comes from a YAML file. Example definition: ${xacro.load_yaml('$(find franka_description)/robots/fr3/inertials.yaml')} -->
  <!-- dynamics: description of the dynamics that comes from a YAML file. Example definition: ${xacro.load_yaml('$(find franka_description)/robots/fr3/dynamics.yaml')} -->
  <link name="base">
      </link>
  <joint name="fr3_base_joint" type="fixed">
    <parent link="base"/>
    <child link="fr3_link0"/>
    <origin rpy="0 0 0" xyz="0 0 0"/>
  </joint>
  <!-- sub-link defining detailed meshes for collision with environment -->
  <link name="fr3_link0">
    <visual name="fr3_link0_visual">
      <geometry>
        <mesh filename="package://franka_description/meshes/robot_arms/fr3/visual/link0.dae"/>
      </geometry>
    </visual>
    <collision name="fr3_link0_collision">
      <geometry>
        <mesh filename="package://franka_description/meshes/robot_arms/fr3/collision/link0.stl"/>
      </geometry>
    </collision>
    <inertial>
      <origin rpy="0 0 0" xyz="-0.0172 0.0004 0.0745"/>
      <mass value="2.3966"/>
      <inertia ixx="0.009" ixy="0.0" ixz="0.002" iyy="0.0115" iyz="0.0" izz="0.0085"/>
    </inertial>
  </link>
  <!-- sub-link defining detailed meshes for collision with environment -->
  <link name="fr3_link1">
    <visual name="fr3_link1_visual">
      <geometry>
        <mesh filename="package://franka_description/meshes/robot_arms/fr3/visual/link1.dae"/>
      </geometry>
    </visual>
    <collision name="fr3_link1_collision">
      <geometry>
        <mesh filename="package://franka_description/meshes/robot_arms/fr3/collision/link1.stl"/>
      </geometry>
    </collision>
    <inertial>
      <origin rpy="0 0 0" xyz="0.0000004128 -0.0181251324 -0.0386035970"/>
      <mass value="2.9274653454"/>
      <inertia ixx="0.023927316485107913" ixy="1.3317903455714081e-05" ixz="-0.00011404774918616684" iyy="0.0224821613275756" iyz="-0.0019950320628240115" izz="0.006350098258530016"/>
    </inertial>
  </link>
  <joint name="fr3_joint1" type="revolute">
    <origin rpy="0 0 0" xyz="0 0 0.333"/>
    <parent link="fr3_link0"/>
    <child link="fr3_link1"/>
    <axis xyz="0 0 1"/>
    <limit effort="87.0" lower="-2.7437" upper="2.7437" velocity="2.62"/>
    <safety_controller k_position="100.0" k_velocity="40.0" soft_lower_limit="-2.7437" soft_upper_limit="2.7437"/>
    <dynamics D="1" K="7000" damping="0.003" friction="0.2" mu_coulomb="0" mu_viscous="16"/>
  </joint>
  <!-- sub-link defining detailed meshes for collision with environment -->
  <link name="fr3_link2">
    <visual name="fr3_link2_visual">
      <geometry>
        <mesh filename="package://franka_description/meshes/robot_arms/fr3/visual/link2.dae"/>
      </geometry>
    </visual>
    <collision name="fr3_link2_collision">
      <geometry>
        <mesh filename="package://franka_description/meshes/robot_arms/fr3/collision/link2.stl"/>
      </geometry>
    </collision>
    <inertial>
      <origin rpy="0 0 0" xyz="0.0031828864 -0.0743221644 0.0088146084"/>
      <mass value="2.9355370338"/>
      <inertia ixx="0.041938946257609425" ixy="0.00020257331521090626" ixz="0.004077784227179924" iyy="0.02514514885014724" iyz="-0.0042252158006570156" izz="0.06170214472888839"/>
    </inertial>
  </link>
  <joint name="fr3_joint2" type="revolute">
    <origin rpy="-1.570796326794897 0 0" xyz="0 0 0"/>
    <parent link="fr3_link1"/>
    <child link="fr3_link2"/>
    <axis xyz="0 0 1"/>
    <limit effort="87.0" lower="-1.7837" upper="1.7837" velocity="2.62"/>
    <safety_controller k_position="100.0" k_velocity="40.0" soft_lower_limit="-1.7837" soft_upper_limit="1.7837"/>
    <dynamics D="1" K="7000" damping="0.003" friction="0.2" mu_coulomb="0" mu_viscous="16"/>
  </joint>
  <!-- sub-link defining detailed meshes for collision with environment -->
  <link name="fr3_link3">
    <visual name="fr3_link3_visual">
      <geometry>
        <mesh filename="package://franka_description/meshes/robot_arms/fr3/visual/link3.dae"/>
      </geometry>
    </visual>
    <collision name="fr3_link3_collision">
      <geometry>
        <mesh filename="package://franka_description/meshes/robot_arms/fr3/collision/link3.stl"/>
      </geometry>
    </collision>
    <inertial>
      <origin rpy="0 0 0" xyz="0.0407015686 -0.0048200565 -0.0289730823"/>
      <mass value="2.2449013699"/>
      <inertia ixx="0.02410142547240885" ixy="0.002404694559042109" ixz="-0.002856269270114313" iyy="0.01974053266708178" iyz="-0.002104212683891874" izz="0.019044494482244823"/>
    </inertial>
  </link>
  <joint name="fr3_joint3" type="revolute">
    <origin rpy="1.570796326794897 0 0" xyz="0 -0.316 0"/>
    <parent link="fr3_link2"/>
    <child link="fr3_link3"/>
    <axis xyz="0 0 1"/>
    <limit effort="87.0" lower="-2.9007" upper="2.9007" velocity="2.62"/>
    <safety_controller k_position="100.0" k_velocity="40.0" soft_lower_limit="-2.9007" soft_upper_limit="2.9007"/>
    <dynamics D="1" K="7000" damping="0.003" friction="0.2" mu_coulomb="0" mu_viscous="16"/>
  </joint>
  <!-- sub-link defining detailed meshes for collision with environment -->
  <link name="fr3_link4">
    <visual name="fr3_link4_visual">
      <geometry>
        <mesh filename="package://franka_description/meshes/robot_arms/fr3/visual/link4.dae"/>
      </geometry>
    </visual>
    <collision name="fr3_link4_collision">
      <geometry>
        <mesh filename="package://franka_description/meshes/robot_arms/fr3/collision/link4.stl"/>
      </geometry>
    </collision>
    <inertial>
      <origin rpy="0 0 0" xyz="-0.0459100965 0.0630492960 -0.0085187868"/>
      <mass value="2.6155955791"/>
      <inertia ixx="0.03452998321913202" ixy="0.01322552265982813" ixz="0.01015142998484113" iyy="0.028881621933049058" iyz="-0.0009762833870704552" izz="0.04125471171146641"/>
    </inertial>
  </link>
  <joint name="fr3_joint4" type="revolute">
    <origin rpy="1.570796326794897 0 0" xyz="0.0825 0 0"/>
    <parent link="fr3_link3"/>
    <child link="fr3_link4"/>
    <axis xyz="0 0 1"/>
    <limit effort="87.0" lower="-3.0421" upper="-0.1518" velocity="2.62"/>
    <safety_controller k_position="100.0" k_velocity="40.0" soft_lower_limit="-3.0421" soft_upper_limit="-0.1518"/>
    <dynamics D="1" K="7000" damping="0.003" friction="0.2" mu_coulomb="0" mu_viscous="16"/>
  </joint>
  <!-- sub-link defining detailed meshes for collision with environment -->
  <link name="fr3_link5">
    <visual name="fr3_link5_visual">
      <geometry>
        <mesh filename="package://franka_description/meshes/robot_arms/fr3/visual/link5.dae"/>
      </geometry>
    </visual>
    <collision name="fr3_link5_collision">
      <geometry>
        <mesh filename="package://franka_description/meshes/robot_arms/fr3/collision/link5.stl"/>
      </geometry>
    </collision>
    <inertial>
      <origin rpy="0 0 0" xyz="-0.0016039605 0.0292536262 -0.0972965990"/>
      <mass value="2.3271207594"/>
      <inertia ixx="0.051610278463662895" ixy="-0.005715173387783472" ixz="-0.0035673167625872135" iyy="0.04787729713371481" iyz="0.010673985108535986" izz="0.016423625579357254"/>
    </inertial>
  </link>
  <joint name="fr3_joint5" type="revolute">
    <origin rpy="-1.570796326794897 0 0" xyz="-0.0825 0.384 0"/>
    <parent link="fr3_link4"/>
    <child link="fr3_link5"/>
    <axis xyz="0 0 1"/>
    <limit effort="12.0" lower="-2.8065" upper="2.8065" velocity="5.26"/>
    <safety_controller k_position="100.0" k_velocity="40.0" soft_lower_limit="-2.8065" soft_upper_limit="2.8065"/>
    <dynamics D="1" K="7000" damping="0.003" friction="0.2" mu_coulomb="0" mu_viscous="16"/>
  </joint>
  <!-- sub-link defining detailed meshes for collision with environment -->
  <link name="fr3_link6">
    <visual name="fr3_link6_visual">
      <geometry>
        <mesh filename="package://franka_description/meshes/robot_arms/fr3/visual/link6.dae"/>
      </geometry>
    </visual>
    <collision name="fr3_link6_collision">
      <geometry>
        <mesh filename="package://franka_description/meshes/robot_arms/fr3/collision/link6.stl"/>
      </geometry>
    </collision>
    <inertial>
      <origin rpy="0 0 0" xyz="0.0597131221 -0.0410294666 -0.0101692726"/>
      <mass value="1.8170376524"/>
      <inertia ixx="0.005412333594383447" ixy="0.006193456360285834" ixz="0.0014219289306117652" iyy="0.014058329545509979" iyz="-0.0013140753741120031" izz="0.016080817924212554"/>
    </inertial>
  </link>
  <joint name="fr3_joint6" type="revolute">
    <origin rpy="1.570796326794897 0 0" xyz="0 0 0"/>
    <parent link="fr3_link5"/>
    <child link="fr3_link6"/>
    <axis xyz="0 0 1"/>
    <limit effort="12.0" lower="0.5445" upper="4.5169" velocity="4.18"/>
    <safety_controller k_position="100.0" k_velocity="40.0" soft_lower_limit="0.5445" soft_upper_limit="4.5169"/>
    <dynamics D="1" K="7000" damping="0.003" friction="0.2" mu_coulomb="0" mu_viscous="16"/>
  </joint>
  <!-- sub-link defining detailed meshes for collision with environment -->
  <link name="fr3_link7">
    <visual name="fr3_link7_visual">
      <geometry>
        <mesh filename="package://franka_description/meshes/robot_arms/fr3/visual/link7.dae"/>
      </geometry>
    </visual>
    <collision name="fr3_link7_collision">
      <geometry>
        <mesh filename="package://franka_description/meshes/robot_arms/fr3/collision/link7.stl"/>
      </geometry>
    </collision>
    <inertial>
      <origin rpy="0 0 0" xyz="0.0045225817 0.0086261921 -0.0161633251"/>
      <mass value="0.6271432862"/>
      <inertia ixx="0.00021092389150104718" ixy="-2.433299114461931e-05" ixz="4.564480393778983e-05" iyy="0.00017718568002411474" iyz="8.744070223226438e-05" izz="5.993190599659971e-05"/>
    </inertial>
  </link>
  <joint name="fr3_joint7" type="revolute">
    <origin rpy="1.570796326794897 0 0" xyz="0.088 0 0"/>
    <parent link="fr3_link6"/>
    <child link="fr3_link7"/>
    <axis xyz="0 0 1"/>
    <limit effort="12.0" lower="-3.0159" upper="3.0159" velocity="5.26"/>
    <safety_controller k_position="100.0" k_velocity="40.0" soft_lower_limit="-3.0159" soft_upper_limit="3.0159"/>
    <dynamics D="1" K="7000" damping="0.003" friction="0.2" mu_coulomb="0" mu_viscous="16"/>
  </joint>
  <link name="fr3_link8"/>
  <joint name="fr3_joint8" type="fixed">
    <origin rpy="0 0 0" xyz="0 0 0.107"/>
    <parent link="fr3_link7"/>
    <child link="fr3_link8"/>
  </joint>

    <!-- Connecting Joint -->
  <joint name="fr3_to_base_joint" type="fixed">
    <origin rpy="0 0 0" xyz="0 0.052 0"/> <!-- Adjust origin as needed -->
    <parent link="fr3_link8"/>
    <child link="base_link"/>
  </joint>

  <link
    name="base_link">
    <inertial>
      <origin
        xyz="-0.195542761308929 -0.0543004566173789 -0.00311358705126816"
        rpy="0 0 0" />
      <mass
        value="2.82497847633582" />
      <inertia
        ixx="0.000691365018399165"
        ixy="-7.21989726832368E-06"
        ixz="-8.28623313768042E-06"
        iyy="0.00220366922516715"
        iyz="9.93940688552824E-06"
        izz="0.0021607307802539" />
    </inertial>
    <visual>
      <origin
        xyz="0 0 0"
        rpy="0 0 0" />
      <geometry>
        <mesh
          filename="package://CSI-200_BoneCuttingToolFullAssy_V4_URDF/meshes/base_link.STL" />
      </geometry>
      <material
        name="">
        <color
          rgba="1 1 1 1" />
      </material>
    </visual>
    <collision>
      <origin
        xyz="0 0 0"
        rpy="0 0 0" />
      <geometry>
        <mesh
          filename="package://CSI-200_BoneCuttingToolFullAssy_V4_URDF/meshes/base_link.STL" />
      </geometry>
    </collision>
  </link>
  <link
    name="link_1">
    <inertial>
      <origin
        xyz="0.0101457727235753 -1.38937210070189E-08 1.73744119369434E-08"
        rpy="0 0 0" />
      <mass
        value="0.000801545700671476" />
      <inertia
        ixx="4.87957028547107E-09"
        ixy="8.24174385783391E-15"
        ixz="5.49944055996202E-15"
        iyy="4.45101627891487E-08"
        iyz="-2.78849773361008E-15"
        izz="4.8971339648408E-08" />
    </inertial>
    <visual>
      <origin
        xyz="0 0 0"
        rpy="0 0 0" />
      <geometry>
        <mesh
          filename="package://CSI-200_BoneCuttingToolFullAssy_V4_URDF/meshes/link_1.STL" />
      </geometry>
      <material
        name="">
        <color
          rgba="1 1 1 1" />
      </material>
    </visual>
    <collision>
      <origin
        xyz="0 0 0"
        rpy="0 0 0" />
      <geometry>
        <mesh
          filename="package://CSI-200_BoneCuttingToolFullAssy_V4_URDF/meshes/link_1.STL" />
      </geometry>
    </collision>
  </link>
  <joint
    name="Joint_1"
    type="revolute">
    <origin
      xyz="0 0 0"
      rpy="0 0 0" />
    <parent
      link="base_link" />
    <child
      link="link_1" />
    <axis
      xyz="0 0 -1" />
    <limit
      lower="0"
      upper="0"
      effort="0"
      velocity="0" />
  </joint>
  <link
    name="link_2">
    <inertial>
      <origin
        xyz="-0.0041346 -4.838E-08 1.8992E-09"
        rpy="0 0 0" />
      <mass
        value="0.0033683" />
      <inertia
        ixx="8.7289E-08"
        ixy="-4.858E-14"
        ixz="-2.9376E-13"
        iyy="2.1214E-07"
        iyz="-3.2726E-09"
        izz="2.175E-07" />
    </inertial>
    <visual>
      <origin
        xyz="0 0 0"
        rpy="0 0 0" />
      <geometry>
        <mesh
          filename="package://CSI-200_BoneCuttingToolFullAssy_V4_URDF/meshes/link_2.STL" />
      </geometry>
      <material
        name="">
        <color
          rgba="1 1 1 1" />
      </material>
    </visual>
    <collision>
      <origin
        xyz="0 0 0"
        rpy="0 0 0" />
      <geometry>
        <mesh
          filename="package://CSI-200_BoneCuttingToolFullAssy_V4_URDF/meshes/link_2.STL" />
      </geometry>
    </collision>
  </link>
  <joint
    name="Joint_2"
    type="revolute">
    <origin
      xyz="0.028 0 0"
      rpy="0 0 0" />
    <parent
      link="link_1" />
    <child
      link="link_2" />
    <axis
      xyz="0 0 1" />
    <limit
      lower="0"
      upper="0"
      effort="0"
      velocity="0" />
  </joint>
  <link
    name="link_3">
    <inertial>
      <origin
        xyz="-0.0102371819343171 -6.95258367544582E-09 6.79990827257004E-08"
        rpy="0 0 0" />
      <mass
        value="0.000776703550787097" />
      <inertia
        ixx="4.54352451091879E-09"
        ixy="-8.73669351483935E-14"
        ixz="-1.17844997889738E-14"
        iyy="4.07691636249048E-08"
        iyz="2.11595273770962E-14"
        izz="4.49040530272986E-08" />
    </inertial>
    <visual>
      <origin
        xyz="0 0 0"
        rpy="0 0 0" />
      <geometry>
        <mesh
          filename="package://CSI-200_BoneCuttingToolFullAssy_V4_URDF/meshes/link_3.STL" />
      </geometry>
      <material
        name="">
        <color
          rgba="1 1 1 1" />
      </material>
    </visual>
    <collision>
      <origin
        xyz="0 0 0"
        rpy="0 0 0" />
      <geometry>
        <mesh
          filename="package://CSI-200_BoneCuttingToolFullAssy_V4_URDF/meshes/link_3.STL" />
      </geometry>
    </collision>
  </link>
  <joint
    name="Joint_3"
    type="revolute">
    <origin
      xyz="0.02 0 0"
      rpy="0 0 0" />
    <parent
      link="link_2" />
    <child
      link="link_3" />
    <axis
      xyz="0 0 1" />
    <limit
      lower="0"
      upper="0"
      effort="0"
      velocity="0" />
  </joint>
  <link
    name="link_4">
    <inertial>
      <origin
        xyz="-0.00413458669102168 -5.31176039264558E-08 1.89923374249723E-09"
        rpy="0 0 0" />
      <mass
        value="0.00336830557166159" />
      <inertia
        ixx="8.7289371529378E-08"
        ixy="-5.08154165546928E-14"
        ixz="-1.65928902421146E-13"
        iyy="2.12140667540327E-07"
        iyz="-3.27257912690215E-09"
        izz="2.1749531315581E-07" />
    </inertial>
    <visual>
      <origin
        xyz="0 0 0"
        rpy="0 0 0" />
      <geometry>
        <mesh
          filename="package://CSI-200_BoneCuttingToolFullAssy_V4_URDF/meshes/link_4.STL" />
      </geometry>
      <material
        name="">
        <color
          rgba="1 1 1 1" />
      </material>
    </visual>
    <collision>
      <origin
        xyz="0 0 0"
        rpy="0 0 0" />
      <geometry>
        <mesh
          filename="package://CSI-200_BoneCuttingToolFullAssy_V4_URDF/meshes/link_4.STL" />
      </geometry>
    </collision>
  </link>
  <joint
    name="Joint_4"
    type="revolute">
    <origin
      xyz="0.008 0 0"
      rpy="0 0 0" />
    <parent
      link="link_3" />
    <child
      link="link_4" />
    <axis
      xyz="0 0 1" />
    <limit
      lower="0"
      upper="0"
      effort="0"
      velocity="0" />
  </joint>
  <link
    name="link_5">
    <inertial>
      <origin
        xyz="-0.00976281806568305 6.95260793381891E-09 6.7999082947745E-08"
        rpy="0 0 0" />
      <mass
        value="0.000776703550787119" />
      <inertia
        ixx="4.54352451091898E-09"
        ixy="-8.73669258551938E-14"
        ixz="1.17844997507639E-14"
        iyy="4.07691636249061E-08"
        iyz="-2.11595273789002E-14"
        izz="4.49040530272999E-08" />
    </inertial>
    <visual>
      <origin
        xyz="0 0 0"
        rpy="0 0 0" />
      <geometry>
        <mesh
          filename="package://CSI-200_BoneCuttingToolFullAssy_V4_URDF/meshes/link_5.STL" />
      </geometry>
      <material
        name="">
        <color
          rgba="1 1 1 1" />
      </material>
    </visual>
    <collision>
      <origin
        xyz="0 0 0"
        rpy="0 0 0" />
      <geometry>
        <mesh
          filename="package://CSI-200_BoneCuttingToolFullAssy_V4_URDF/meshes/link_5.STL" />
      </geometry>
    </collision>
  </link>
  <joint
    name="Joint_5"
    type="revolute">
    <origin
      xyz="0.02 0 0"
      rpy="0 0 0" />
    <parent
      link="link_4" />
    <child
      link="link_5" />
    <axis
      xyz="0 0 1" />
    <limit
      lower="0"
      upper="0"
      effort="0"
      velocity="0" />
  </joint>
  <link
    name="link_6">
    <inertial>
      <origin
        xyz="-0.0041346 -5.4614E-08 1.8992E-09"
        rpy="0 0 0" />
      <mass
        value="0.0033683" />
      <inertia
        ixx="8.7289E-08"
        ixy="-6.1181E-14"
        ixz="-9.4893E-14"
        iyy="2.1214E-07"
        iyz="-3.2726E-09"
        izz="2.175E-07" />
    </inertial>
    <visual>
      <origin
        xyz="0 0 0"
        rpy="0 0 0" />
      <geometry>
        <mesh
          filename="package://CSI-200_BoneCuttingToolFullAssy_V4_URDF/meshes/link_6.STL" />
      </geometry>
      <material
        name="">
        <color
          rgba="1 1 1 1" />
      </material>
    </visual>
    <collision>
      <origin
        xyz="0 0 0"
        rpy="0 0 0" />
      <geometry>
        <mesh
          filename="package://CSI-200_BoneCuttingToolFullAssy_V4_URDF/meshes/link_6.STL" />
      </geometry>
    </collision>
  </link>
  <joint
    name="Joint_6"
    type="revolute">
    <origin
      xyz="0.008 0 0"
      rpy="0 0 0" />
    <parent
      link="link_5" />
    <child
      link="link_6" />
    <axis
      xyz="0 0 1" />
    <limit
      lower="0"
      upper="0"
      effort="0"
      velocity="0" />
  </joint>
  <link
    name="link_7">
    <inertial>
      <origin
        xyz="-0.0101457727235751 1.38937032434505E-08 1.737441177041E-08"
        rpy="0 0 0" />
      <mass
        value="0.000801545700671478" />
      <inertia
        ixx="4.87957028547109E-09"
        ixy="8.24176223841101E-15"
        ixz="-5.49944063782202E-15"
        iyy="4.45101627891479E-08"
        iyz="2.78849774344208E-15"
        izz="4.89713396484073E-08" />
    </inertial>
    <visual>
      <origin
        xyz="0 0 0"
        rpy="0 0 0" />
      <geometry>
        <mesh
          filename="package://CSI-200_BoneCuttingToolFullAssy_V4_URDF/meshes/link_7.STL" />
      </geometry>
      <material
        name="">
        <color
          rgba="1 1 1 1" />
      </material>
    </visual>
    <collision>
      <origin
        xyz="0 0 0"
        rpy="0 0 0" />
      <geometry>
        <mesh
          filename="package://CSI-200_BoneCuttingToolFullAssy_V4_URDF/meshes/link_7.STL" />
      </geometry>
    </collision>
  </link>
  <joint
    name="Joint_7"
    type="revolute">
    <origin
      xyz="0.02 0 0"
      rpy="0 0 0" />
    <parent
      link="link_6" />
    <child
      link="link_7" />
    <axis
      xyz="0 0 1" />
    <limit
      lower="0"
      upper="0"
      effort="0"
      velocity="0" />
  </joint>
  <link
    name="link_8">
    <inertial>
      <origin
        xyz="-0.00413459043224676 -5.42795224878212E-08 1.89923382576396E-09"
        rpy="0 0 0" />
      <mass
        value="0.00336830557166155" />
      <inertia
        ixx="8.72893847155127E-08"
        ixy="-5.77927943524461E-14"
        ixz="-1.14282567555678E-13"
        iyy="2.12140654354189E-07"
        iyz="-3.27258604345153E-09"
        izz="2.17495313155808E-07" />
    </inertial>
    <visual>
      <origin
        xyz="0 0 0"
        rpy="0 0 0" />
      <geometry>
        <mesh
          filename="package://CSI-200_BoneCuttingToolFullAssy_V4_URDF/meshes/link_8.STL" />
      </geometry>
      <material
        name="">
        <color
          rgba="1 1 1 1" />
      </material>
    </visual>
    <collision>
      <origin
        xyz="0 0 0"
        rpy="0 0 0" />
      <geometry>
        <mesh
          filename="package://CSI-200_BoneCuttingToolFullAssy_V4_URDF/meshes/link_8.STL" />
      </geometry>
    </collision>
  </link>
  <joint
    name="Joint_8"
    type="revolute">
    <origin
      xyz="0.008 0 0"
      rpy="0 0 0" />
    <parent
      link="link_7" />
    <child
      link="link_8" />
    <axis
      xyz="0 0 1" />
    <limit
      lower="0"
      upper="0"
      effort="0"
      velocity="0" />
  </joint>
  <link
    name="link_9">
    <inertial>
      <origin
        xyz="-0.0101457727235744 1.38935972171517E-08 1.73744119369434E-08"
        rpy="0 0 0" />
      <mass
        value="0.000801545700671512" />
      <inertia
        ixx="4.87957028547128E-09"
        ixy="8.24175386493798E-15"
        ixz="-5.49944063220866E-15"
        iyy="4.45101627891502E-08"
        iyz="2.78849776675144E-15"
        izz="4.89713396484096E-08" />
    </inertial>
    <visual>
      <origin
        xyz="0 0 0"
        rpy="0 0 0" />
      <geometry>
        <mesh
          filename="package://CSI-200_BoneCuttingToolFullAssy_V4_URDF/meshes/link_9.STL" />
      </geometry>
      <material
        name="">
        <color
          rgba="1 1 1 1" />
      </material>
    </visual>
    <collision>
      <origin
        xyz="0 0 0"
        rpy="0 0 0" />
      <geometry>
        <mesh
          filename="package://CSI-200_BoneCuttingToolFullAssy_V4_URDF/meshes/link_9.STL" />
      </geometry>
    </collision>
  </link>
  <joint
    name="Joint_9"
    type="revolute">
    <origin
      xyz="0.02 0 0"
      rpy="0 0 0" />
    <parent
      link="link_8" />
    <child
      link="link_9" />
    <axis
      xyz="0 0 1" />
    <limit
      lower="0"
      upper="0"
      effort="0"
      velocity="0" />
  </joint>
  <link
    name="jaw">
    <inertial>
      <origin
        xyz="-0.0162494788517108 0.00970487538356685 -5.29411001148894E-09"
        rpy="0 0 0" />
      <mass
        value="0.0203919851208377" />
      <inertia
        ixx="7.44462850114211E-07"
        ixy="1.14189498281302E-07"
        ixz="1.80284060821887E-12"
        iyy="5.57865257909692E-07"
        iyz="-2.2650481430213E-09"
        izz="9.15710154261717E-07" />
    </inertial>
    <visual>
      <origin
        xyz="0 0 0"
        rpy="0 0 0" />
      <geometry>
        <mesh
          filename="package://CSI-200_BoneCuttingToolFullAssy_V4_URDF/meshes/jaw.STL" />
      </geometry>
      <material
        name="">
        <color
          rgba="1 1 1 1" />
      </material>
    </visual>
    <collision>
      <origin
        xyz="0 0 0"
        rpy="0 0 0" />
      <geometry>
        <mesh
          filename="package://CSI-200_BoneCuttingToolFullAssy_V4_URDF/meshes/jaw.STL" />
      </geometry>
    </collision>
  </link>
  <joint
    name="jaw"
    type="fixed">
    <origin
      xyz="0.039 -0.0105 0"
      rpy="0 0 0" />
    <parent
      link="link_9" />
    <child
      link="jaw" />
    <axis
      xyz="0 0 0" />
  </joint>








  <disable_collision link1="base" link2="fr3_link0">
  </disable_collision>
  <disable_collision link1="fr3_link0" link2="fr3_link1">
  </disable_collision>
  <disable_collision link1="fr3_link1" link2="fr3_link2">
  </disable_collision>
  <disable_collision link1="fr3_link2" link2="fr3_link3">
  </disable_collision>
  <disable_collision link1="fr3_link3" link2="fr3_link4">
  </disable_collision>
  <disable_collision link1="fr3_link4" link2="fr3_link5">
  </disable_collision>
  <disable_collision link1="fr3_link5" link2="fr3_link6">
  </disable_collision>
  <disable_collision link1="fr3_link6" link2="fr3_link7">
  </disable_collision>
  <disable_collision link1="fr3_link7" link2="fr3_link8">
  </disable_collision>


</robot>
